Workbook

Sheet Senarai Semak
A1: Senarai Semak Audit Halal: Skim Produk Kosmetik
A2: Premis/syarikat: ______________________________ Jenis produk / no. notifikasi NPRA: __________ Tarikh: ____________ Juruaudit: ______________________
A3: Ya = patuh, Tidak = tidak patuh, TB = tidak berkaitan. Rujukan bertanda * = hanya tajuk klausa disahkan dari pratonton rasmi JSM; isi diringkaskan. Senarai rujukan penuh di helaian 'Rujukan'.
A5: No | B5: Keperluan | C5: Rujukan | D5: Ya/Tidak/TB | E5: Bukti / Catatan
A6: Bahagian A: Kelayakan, Lesen, Notifikasi NPRA & Skop Permohonan
A7: Semak dokumen pendaftaran, lesen, notifikasi NPRA dan skop produk dalam MYeHALAL, kemudian padankan dengan produk yang sebenarnya dikeluarkan di kilang.
A8: A1 | B8: Pendaftaran perniagaan (SSM, koperasi atau dokumen penubuhan) masih sah, dan nama serta alamatnya sama dengan permohonan SPHM. | C8: MPPHM 5(1) | F8: A
A9: A2 | B9: Lesen atau kelulusan PBT bagi premis kilang, atau surat sokongan agensi kerajaan yang berkaitan, masih sah dan sepadan dengan alamat kilang. | C9: MPPHM 5(2) | F9: A
A10: A3 | B10: Kilang telah beroperasi sepenuhnya sekurang-kurangnya 3 bulan sebelum memohon (pemohon baharu), atau sekurang-kurangnya 1 bulan di premis baharu (pindah premis). | C10: MPPHM 5(7), 5(8) | F10: A
A11: A4 | B11: Setiap produk kosmetik yang dipohon telah dinotifikasikan kepada NPRA, atau syarikat memegang surat kebenaran bertulis NPRA untuk mengilang produk kosmetik tidak bernotifikasi bagi tujuan eksport sahaja (FEO). | C11: MPPHM 18(2)(a); PKDK 1984 per. 18A(1)(a), 18A(3)(b); GKPK 7.3 | F11: A
A12: A5 | B12: Dokumen 'Notification Detail(s)' daripada NPRA telah dikemukakan dalam permohonan bagi setiap produk kosmetik yang dipohon, termasuk setiap varian. | C12: MPPHM 18(2)(d) | F12: A
A13: A6 | B13: Notifikasi setiap produk masih sah (tempoh sah 2 tahun), dan pembaharuan dibuat tidak lewat 1 bulan sebelum tamat tempoh. Tiada produk yang nota notifikasinya telah dibatalkan oleh Pengarah. | C13: GKPK 2.7, 5.2; PKDK 1984 per. 18A(1)(g), 18A(8) | F13: A
A14: A7 | B14: Pemegang notifikasi kosmetik (CNH) ialah syarikat atau entiti tempatan yang berdaftar dengan SSM. Jika pemilik produk berbeza daripada CNH, surat kebenaran (LOA) tersedia. | C14: GKPK 2.1, Glosari; PKDK 1984 per. 18A(1)(b) | F14: A
A15: A8 | B15: Butiran dalam Notification Detail(s) (nama produk, varian, nama dan alamat pengilang) sepadan dengan premis yang diaudit dan senarai produk dalam MYeHALAL. | C15: MPPHM 18(2)(d), 17(2)(c) | F15: A
A16: A9 | B16: Perubahan pada produk bernotifikasi (cth. bahan, pengilang atau nama produk) telah dikemukakan kepada NPRA mengikut jenis perubahan, iaitu Jenis 1 (pindaan notifikasi) atau Jenis 2 (notifikasi baharu). | C16: GKPK 2.9, Annex I Part 5 | F16: A
A17: A10 | B17: Produk FEO (jika ada): rekod dan dokumen disimpan dan sedia untuk pemeriksaan NPRA, dan keperluan negara penerima dipatuhi. | C17: GKPK 7.3 | F17: A
A18: A11 | B18: Syarikat hanya mengeluarkan dan mengendalikan produk halal, termasuk produk dagangan, produk eksport dan produk yang dikilangkan untuk pihak lain. Tiada produk tidak halal dikeluarkan atau diedarkan. | C18: MPPHM 5(9), 6(1), 6(2) | F18: A
A19: A12 | B19: Jenama yang sama tidak digunakan bagi produk halal dan produk tidak halal. | C19: MPPHM 6(3) | F19: A
... A30: A23 | B30: Pengilangan kontrak: jika kilang turut mengilang kosmetik untuk jenama pihak lain, kilang telah memegang SPHM skim Pengilangan Kontrak/OEM yang sah sebelum menawarkan perkhidmatan itu. | C30: MPPHM 17(17)(a) | F30: A
A31: Bahagian B: Pengurusan Halal, Pekerja Muslim & MHMS mengikut Saiz Industri
A32: Semak manual HAS atau IHCS, surat lantikan, jadual syif, minit JKHD, laporan audit dalaman dan semakan HAS, kemudian sahkan melalui temu bual dengan pengurusan, Eksekutif atau Penyelia Halal dan pekerja.
A33: B1 | B33: Kategori industri ditentukan dengan betul berdasarkan nilai perolehan tahunan untuk menentukan sama ada HAS atau IHCS diperlukan. Kategorinya ialah mikro (kurang daripada RM300,000), kecil (RM300,000 hingga kurang daripada RM15 juta), sederhana (RM15 juta hingga RM50 juta) dan besar (melebihi RM50 juta). | C33: MPPHM 8 (Jadual 1), 18(2)(e) | F33: B
A34: B2 | B34: Pengurusan atasan menunjukkan komitmen terhadap halal dan integriti halal: tanggungjawab halal ditetapkan, dan sumber kewangan, infrastruktur serta tenaga kerja yang mencukupi disediakan. | C34: MS 2634 kl. 4.1* | F34: B
A35: B3 | B35: Polisi halal bertulis diluluskan pengurusan atasan, dipamerkan dan disebarkan kepada pekerja dan pihak berkepentingan. Pekerja yang ditemu bual dapat menerangkannya. | C35: MHMS 5(2), 6(1); MS 2634 kl. 4.1* | F35: B
A36: B4 | B36: Besar/sederhana: sekurang-kurangnya 2 pekerja Muslim warganegara Malaysia berjawatan tetap (tidak termasuk Eksekutif Halal) dilantik dan bertugas di kawasan pemprosesan sepanjang tempoh operasi atau setiap syif. | C36: MPPHM 18(2)(e)(i), 3 | F36: B
A37: B5 | B37: Kecil/mikro: sekurang-kurangnya 1 pekerja Muslim warganegara Malaysia berjawatan tetap (tidak termasuk Penyelia Halal) dilantik dan bertugas di kawasan pemprosesan sepanjang tempoh operasi atau setiap syif. | C37: MPPHM 18(2)(e)(ii), 18(2)(e)(iii), 3 | F37: B
A38: B6 | B38: Pekerja Muslim yang dilantik hadir dan bertugas di kawasan pemprosesan semasa audit, dan surat lantikan tetap serta salinan MyKad mereka tersedia. | C38: MPPHM 17(9)(a), 18(2)(e) | F38: B
A39: B7 | B39: Besar/sederhana: Eksekutif Halal dilantik secara rasmi dan bertulis oleh pengurusan tertinggi bagi setiap cawangan premis. | C39: MPPHM 18(2)(e)(i); MHMS 5(3), 7(1)(a)(iii) | F39: B
A40: B8 | B40: Besar/sederhana: Eksekutif Halal memenuhi kelayakan berikut: Muslim, warganegara Malaysia dan berjawatan tetap; berkelulusan sekurang-kurangnya Diploma Pengurusan Halal atau setara, atau berpengalaman sekurang-kurangnya 5 tahun dalam pengurusan halal; dan memiliki Sijil Eksekutif Halal daripada penyedia latihan yang berdaftar dengan HPB JAKIM. | C40: MPPHM 3; MHMS 5(3) | F40: B
A41: B9 | B41: Besar/sederhana: Eksekutif Halal melaksanakan tugas yang ditetapkan, termasuk mengawal dan mengemas kini manual HAS dan menyelaras aktiviti JKHD. | C41: MHMS 5(3), Lampiran B | F41: B
A42: B10 | B42: Kecil: Penyelia Halal (Muslim, warganegara Malaysia, berjawatan tetap) dilantik di premis, dan bertugas menyelia di kawasan pemprosesan dan/atau bahagian pengurusan. | C42: MPPHM 18(2)(e)(ii), 3 | F42: B
A43: B11 | B43: Besar/sederhana: JKHD ditubuhkan bagi premis dan bagi setiap cawangan yang mempunyai pengurusan operasi yang berbeza, dan dilantik secara rasmi dan bertulis oleh pengurusan tertinggi. | C43: MPPHM 18(2)(e)(i), 3; MHMS 5(4) | F43: B
A44: B12 | B44: Besar/sederhana: JKHD mempunyai sekurang-kurangnya 4 ahli berjawatan tetap (Pengerusi, Eksekutif Halal, wakil pembelian dan/atau perolehan, dan wakil pemprosesan) serta wakil Bahagian R&D. Peranan, tanggungjawab dan terma rujukan JKHD dinyatakan dalam manual HAS, dan carta organisasi JKHD tersedia. | C44: MHMS 5(4), 7(1)(a)(i), Lampiran C1, C2 | F44: B
... A58: B26 | B58: Salinan terkini MPPHM, MHMS, MS 2634, PKDK 1984, fatwa dan pekeliling halal, serta garis panduan kosmetik NPRA (GKPK), disimpan, dan perubahan yang dikehendaki telah dilaksanakan. | C58: MPPHM 17(16)(a), 17(16)(b), 18(2)(c); MS 2634 kl. 4.8* | F58: B
A59: Bahagian C: Sistem Kualiti GMP Kosmetik & Tanggungjawab Pemegang Notifikasi
A60: Semak laporan pemeriksaan GMP NPRA, carta organisasi pengeluaran dan QC, laporan audit dalaman GMP, kontrak pengilangan atau analisis, serta rekod aduan dan kesan advers.
A61: C1 | B61: Bukti pematuhan GMP Kosmetik tersedia: laporan pemeriksaan GMP oleh NPRA (pemeriksaan sebelum notifikasi bagi kilang atau talian pengeluaran baharu, dan pemeriksaan berkala) serta bukti penutupan tindakan pembetulan. | C61: MPPHM 18(2)(b); GKPK 3.7 | F61: C
A62: C2 | B62: Sistem pengurusan kualiti dibangunkan, didokumenkan dan dilaksanakan. | C62: GMP Kosmetik 1.2 | F62: C
A63: C3 | B63: Bahagian pengeluaran dan bahagian kawalan kualiti (QC) diketuai oleh orang yang berbeza, dan kedua-duanya tidak bertanggungjawab antara satu sama lain. | C63: GMP Kosmetik 2.1.1 | F63: C
A64: C4 | B64: Ketua pengeluaran dan ketua QC terlatih dan berpengalaman. Ketua QC berkuasa penuh untuk menetapkan prosedur kawalan kualiti dan untuk meluluskan atau menolak bahan dan produk. | C64: GMP Kosmetik 2.1.2, 2.1.3 | F64: C
...

Sheet Ringkasan
A1: Ringkasan keputusan: Skim Produk Kosmetik
A3: Bahagian | B3: Item | C3: Ya | D3: Tidak | E3: TB | F3: Belum diisi | G3: % patuh (Ya / (Ya+Tidak))
A4: A: Kelayakan, Lesen, Notifikasi NPRA & Skop Permohonan | B4: 23 | C4: =COUNTIFS('Senarai Semak'!$F$6:$F$264,"A",'Senarai Semak'!$D$6:$D$264,"Ya") | D4: =COUNTIFS('Senarai Semak'!$F$6:$F$264,"A",'Senarai Semak'!$D$6:$D$264,"Tidak") | E4: =COUNTIFS('Senarai Semak'!$F$6:$F$264,"A",'Senarai Semak'!$D$6:$D$264,"TB") | F4: =B4-C4-D4-E4 | G4: =IF(C4+D4=0,"",C4/(C4+D4))
A5: B: Pengurusan Halal, Pekerja Muslim & MHMS mengikut Saiz Industri | B5: 26 | C5: =COUNTIFS('Senarai Semak'!$F$6:$F$264,"B",'Senarai Semak'!$D$6:$D$264,"Ya") | D5: =COUNTIFS('Senarai Semak'!$F$6:$F$264,"B",'Senarai Semak'!$D$6:$D$264,"Tidak") | E5: =COUNTIFS('Senarai Semak'!$F$6:$F$264,"B",'Senarai Semak'!$D$6:$D$264,"TB") | F5: =B5-C5-D5-E5 | G5: =IF(C5+D5=0,"",C5/(C5+D5))
A6: C: Sistem Kualiti GMP Kosmetik & Tanggungjawab Pemegang Notifikasi | B6: 12 | C6: =COUNTIFS('Senarai Semak'!$F$6:$F$264,"C",'Senarai Semak'!$D$6:$D$264,"Ya") | D6: =COUNTIFS('Senarai Semak'!$F$6:$F$264,"C",'Senarai Semak'!$D$6:$D$264,"Tidak") | E6: =COUNTIFS('Senarai Semak'!$F$6:$F$264,"C",'Senarai Semak'!$D$6:$D$264,"TB") | F6: =B6-C6-D6-E6 | G6: =IF(C6+D6=0,"",C6/(C6+D6))
A7: D: Premis, Persekitaran & Bekalan Air | B7: 18 | C7: =COUNTIFS('Senarai Semak'!$F$6:$F$264,"D",'Senarai Semak'!$D$6:$D$264,"Ya") | D7: =COUNTIFS('Senarai Semak'!$F$6:$F$264,"D",'Senarai Semak'!$D$6:$D$264,"Tidak") | E7: =COUNTIFS('Senarai Semak'!$F$6:$F$264,"D",'Senarai Semak'!$D$6:$D$264,"TB") | F7: =B7-C7-D7-E7 | G7: =IF(C7+D7=0,"",C7/(C7+D7))
A8: E: Bahan Mentah, Bahan Kritikal & Pembekal | B8: 26 | C8: =COUNTIFS('Senarai Semak'!$F$6:$F$264,"E",'Senarai Semak'!$D$6:$D$264,"Ya") | D8: =COUNTIFS('Senarai Semak'!$F$6:$F$264,"E",'Senarai Semak'!$D$6:$D$264,"Tidak") | E8: =COUNTIFS('Senarai Semak'!$F$6:$F$264,"E",'Senarai Semak'!$D$6:$D$264,"TB") | F8: =B8-C8-D8-E8 | G8: =IF(C8+D8=0,"",C8/(C8+D8))
A9: F: Penyimpanan Bahan & Produk | B9: 14 | C9: =COUNTIFS('Senarai Semak'!$F$6:$F$264,"F",'Senarai Semak'!$D$6:$D$264,"Ya") | D9: =COUNTIFS('Senarai Semak'!$F$6:$F$264,"F",'Senarai Semak'!$D$6:$D$264,"Tidak") | E9: =COUNTIFS('Senarai Semak'!$F$6:$F$264,"F",'Senarai Semak'!$D$6:$D$264,"TB") | F9: =B9-C9-D9-E9 | G9: =IF(C9+D9=0,"",C9/(C9+D9))
A10: G: Penimbangan, Pengeluaran & Pembungkusan | B10: 18 | C10: =COUNTIFS('Senarai Semak'!$F$6:$F$264,"G",'Senarai Semak'!$D$6:$D$264,"Ya") | D10: =COUNTIFS('Senarai Semak'!$F$6:$F$264,"G",'Senarai Semak'!$D$6:$D$264,"Tidak") | E10: =COUNTIFS('Senarai Semak'!$F$6:$F$264,"G",'Senarai Semak'!$D$6:$D$264,"TB") | F10: =B10-C10-D10-E10 | G10: =IF(C10+D10=0,"",C10/(C10+D10))
A11: H: Peralatan, Utiliti & Bahan Bantu Pemprosesan | B11: 13 | C11: =COUNTIFS('Senarai Semak'!$F$6:$F$264,"H",'Senarai Semak'!$D$6:$D$264,"Ya") | D11: =COUNTIFS('Senarai Semak'!$F$6:$F$264,"H",'Senarai Semak'!$D$6:$D$264,"Tidak") | E11: =COUNTIFS('Senarai Semak'!$F$6:$F$264,"H",'Senarai Semak'!$D$6:$D$264,"TB") | F11: =B11-C11-D11-E11 | G11: =IF(C11+D11=0,"",C11/(C11+D11))
A12: I: Kawalan Kualiti, Makmal & Analisis Halal | B12: 14 | C12: =COUNTIFS('Senarai Semak'!$F$6:$F$264,"I",'Senarai Semak'!$D$6:$D$264,"Ya") | D12: =COUNTIFS('Senarai Semak'!$F$6:$F$264,"I",'Senarai Semak'!$D$6:$D$264,"Tidak") | E12: =COUNTIFS('Senarai Semak'!$F$6:$F$264,"I",'Senarai Semak'!$D$6:$D$264,"TB") | F12: =B12-C12-D12-E12 | G12: =IF(C12+D12=0,"",C12/(C12+D12))
A13: J: Kebersihan, Sanitasi, Kawalan Perosak & Sisa | B13: 10 | C13: =COUNTIFS('Senarai Semak'!$F$6:$F$264,"J",'Senarai Semak'!$D$6:$D$264,"Ya") | D13: =COUNTIFS('Senarai Semak'!$F$6:$F$264,"J",'Senarai Semak'!$D$6:$D$264,"Tidak") | E13: =COUNTIFS('Senarai Semak'!$F$6:$F$264,"J",'Senarai Semak'!$D$6:$D$264,"TB") | F13: =B13-C13-D13-E13 | G13: =IF(C13+D13=0,"",C13/(C13+D13))
A14: K: Pekerja, Latihan & Kemudahan | B14: 18 | C14: =COUNTIFS('Senarai Semak'!$F$6:$F$264,"K",'Senarai Semak'!$D$6:$D$264,"Ya") | D14: =COUNTIFS('Senarai Semak'!$F$6:$F$264,"K",'Senarai Semak'!$D$6:$D$264,"Tidak") | E14: =COUNTIFS('Senarai Semak'!$F$6:$F$264,"K",'Senarai Semak'!$D$6:$D$264,"TB") | F14: =B14-C14-D14-E14 | G14: =IF(C14+D14=0,"",C14/(C14+D14))
A15: L: Bahan Pembungkusan, Pelabelan, Logo Halal & Tuntutan | B15: 19 | C15: =COUNTIFS('Senarai Semak'!$F$6:$F$264,"L",'Senarai Semak'!$D$6:$D$264,"Ya") | D15: =COUNTIFS('Senarai Semak'!$F$6:$F$264,"L",'Senarai Semak'!$D$6:$D$264,"Tidak") | E15: =COUNTIFS('Senarai Semak'!$F$6:$F$264,"L",'Senarai Semak'!$D$6:$D$264,"TB") | F15: =B15-C15-D15-E15 | G15: =IF(C15+D15=0,"",C15/(C15+D15))
A16: M: Pengangkutan, Kebolehkesanan & Penarikan Balik | B16: 11 | C16: =COUNTIFS('Senarai Semak'!$F$6:$F$264,"M",'Senarai Semak'!$D$6:$D$264,"Ya") | D16: =COUNTIFS('Senarai Semak'!$F$6:$F$264,"M",'Senarai Semak'!$D$6:$D$264,"Tidak") | E16: =COUNTIFS('Senarai Semak'!$F$6:$F$264,"M",'Senarai Semak'!$D$6:$D$264,"TB") | F16: =B16-C16-D16-E16 | G16: =IF(C16+D16=0,"",C16/(C16+D16))
A17: N: Dokumentasi & Rekod | B17: 9 | C17: =COUNTIFS('Senarai Semak'!$F$6:$F$264,"N",'Senarai Semak'!$D$6:$D$264,"Ya") | D17: =COUNTIFS('Senarai Semak'!$F$6:$F$264,"N",'Senarai Semak'!$D$6:$D$264,"Tidak") | E17: =COUNTIFS('Senarai Semak'!$F$6:$F$264,"N",'Senarai Semak'!$D$6:$D$264,"TB") | F17: =B17-C17-D17-E17 | G17: =IF(C17+D17=0,"",C17/(C17+D17))
A18: Jumlah | B18: =SUM(B4:B17) | C18: =SUM(C4:C17) | D18: =SUM(D4:D17) | E18: =SUM(E4:E17) | F18: =SUM(F4:F17) | G18: =IF(C18+D18=0,"",C18/(C18+D18))

Sheet Penemuan
A1: Penemuan dan tindakan pembetulan
A3: No item | B3: Penemuan | C3: Kategori | D3: Tindakan pembetulan | E3: Tarikh siap | F3: PIC
A21: Tandatangan juruaudit: ____________________ Wakil syarikat: ____________________ Pengurusan atasan: ____________________

Sheet Rujukan
A1: Rujukan | B1: Dokumen penuh | C1: Cara disemak | D1: Pautan
A2: MPPHM | B2: Manual Prosedur Pensijilan Halal Malaysia (Domestik) 2020 (JAKIM/JAIN/MAIN) | C2: Teks penuh dibaca (salinan PDF di laman JAIPs) bagi s. 3 (tafsiran), 5, 6, 8 (Jadual 1: kategori industri mengikut perolehan tahunan), 17 dan 18(2)(a)-(e), termasuk 18(2)(e)(i)-(iii). Bagi s. 19, 20, 34-36 dan 40-41, hanya tajuk dalam jadual kandungan yang disemak kerana teks badannya tiada dalam salinan yang diekstrak. | D2: https://jaips.perlis.gov.my/phocadownload/MPPHM%20Domestik%202020%20JAKIM-JAIN.pdf
A3: MHMS | B3: Sistem Pengurusan Halal Malaysia (Malaysian Halal Management System) 2020, JAKIM | C3: Teks penuh dibaca daripada salinan dokumen rasmi JAKIM di serunai.com (https://serunai.com/wp-content/uploads/2023/03/SPHM-2020.pdf). Bahagian yang dibaca: 5(1)-5(13) (HAS), 6(1)-6(3) (IHCS), 7(1)(a)-(b) (skim Produk Makanan & Minuman, Kosmetik, Farmaseutikal, Barang Gunaan dan Peranti Perubatan), 8 dan Lampiran (termasuk Lampiran B, C1, C2 dan D). Rujukan mengikut penomboran yang dicetak dalam manual. | D3: https://myehalal.halal.gov.my/portal-halal/v1/pdf/panduan/MHMS2020.pdf
A4: MS 2634 | B4: MS 2634:2019 Halal cosmetics - General requirements (First revision), Jabatan Standard Malaysia (disahkan semula 2025; menggantikan MS 2200-1:2008) | C4: Pratonton rasmi MySOL dibuka, tetapi hanya jadual kandungan dan Prakata yang kelihatan. Jadual kandungan: 1-3; 4.1 Management responsibility; 4.2 Materials; 4.3 Hygiene, sanitation and safety in the manufacturing and handling of halal cosmetics; 4.4 Other aspects in preparation of materials for halal cosmetics; 4.5 Product manufacturing, handling and distribution; 4.6 Packaging, labelling and advertising; 4.7 Other requirements; 4.8 Legal requirements; 5 Compliance; 6 Halal certificates; 7 Halal certification mark; Lampiran A Method of sertu. Teks klausa tidak kelihatan, jadi semua rujukan bertanda * dan isinya diringkaskan berdasarkan tajuk klausa. Prakata menyatakan bahawa kl. 4.1 ditambah dengan keperluan integriti halal, pengurusan rekod, amalan agama dan penglibatan pekerja. | D4: https://mysol.jsm.gov.my/preview-file/eyJpdiI6Ikd5MjcxbG9ZUFJRUHNpSFNtd3JiYnc9PSIsInZhbHVlIjoiZWdZdDdsb2cvc0x6aElzdFpYYXI1Zz09IiwibWFjIjoiZmYzZmQwYzE0N2E4MjI4MDRjYmUwOGU5MjhkNGE5ZDMxNTczOTIyMDAzNjQyZDdhYjJiYTlmNTJhZjM2NDJjMCJ9
A5: PKDK 1984 | B5: Peraturan-Peraturan Kawalan Dadah dan Kosmetik 1984 (Control of Drugs and Cosmetics Regulations 1984, P.U.(A) 223/1984, versi disatukan dengan pindaan) | C5: Teks penuh dibaca bagi per. 2, 7, 15, 18A (Bahagian IIIA: notifikasi kosmetik, termasuk 18A(1), (3)(b) dan (8)-(14)), 19-25 (Bahagian IV), 26, 27 dan 29. Dalam Bahagian IV, per. 20, 21, 23, 24 dan 25 terpakai kepada pengilang kosmetik bernotifikasi, manakala per. 19 dan 22 tidak terpakai. | D5: https://pharmacy.moh.gov.my/sites/default/files/document-upload/control-drugs-and-cosmetics-regulations-1984.pdf
A6: GKPK | B6: Guidelines for Control of Cosmetic Products in Malaysia, Edisi Kedua (berkuat kuasa 1 Ogos 2022), NPRA, Kementerian Kesihatan Malaysia | C6: Teks penuh dibaca bagi s. 2.1, 2.7, 2.9, 3.3, 3.4, 3.5, 3.7, 3.8, 4.3, 4.4, 5.2, 5.3, 7.3 dan Glosari. Bagi s. 3.6, hanya tajuknya disemak. MPPHM 18(2)(c) menyebut edisi 2017, tetapi rujukan dalam senarai ini mengikut edisi semasa. | D6: https://www.npra.gov.my/images/Guidelines_Central/Guidelines_on_Cosmetic/GUIDELINES_FOR_CONTROL_OF_COSMETIC_PRODUCTS_IN_MALAYSIA.pdf
A7: GMP Kosmetik | B7: Guidelines for Control of Cosmetic Products in Malaysia, Annex I Part 11: Guideline for Cosmetic Good Manufacturing Practice (Edisi Kedua, Ogos 2022) | C7: Teks penuh dibaca, dan nombor seksyen 1.2-13.6 disemak semula. MPPHM 18(2)(b) menyebut 'Annex I, Part 10: Guideline for Cosmetic GMP' (edisi 2017). Dalam edisi 2022, garis panduan GMP (berasaskan ASEAN Cosmetic GMP) ialah Annex I Part 11, manakala Part 10 kini Garis Panduan Iklan Kosmetik. | D7: https://www.npra.gov.my/images/Guidelines_Central/Guidelines_on_Cosmetic/Annex_I_part_11-GUIDELINE_FOR_COSMETIC_GOOD_MANUFACTURING_PRACTICE.pdf
A8: GKPK Annex I | B8: GKPK Annex I (Edisi Kedua, Ogos 2022): Part 2 Non-Permissible Product Names, Part 5 Types of Changes for Notified Products, Part 7 Labelling Requirements, Part 8 Cosmetic Claims, Part 9(ii) Hand Sanitizer Products, Part 10 Cosmetic Advertisement, Part 13 Product Information File (PIF), Part 14 Heavy Metal & Microbiological Test Limits, Part 15 Adverse Event Reporting, Part 16 Guidance for Industry - Reporting and Recall of Cosmetic Product | C8: Teks penuh dibaca bagi Part 2, 7, 8, 9(ii), 10, 13 dan 14. Bagi Part 16, s. 5.1 (tempoh notis penarikan balik sukarela) disemak. Part 5 dan Part 15 hanya dirujuk melalui teks utama GKPK dan tajuk dokumen. | D8: https://www.npra.gov.my/index.php/en/cosmetics-guideline-annex-i-vii
A9: ACD | B9: ASEAN Cosmetic Directive: Annex II (bahan dilarang), Annex III (bahan terhad), Annex IV (pewarna dibenarkan), Annex VI (pengawet dibenarkan) dan Annex VII (penapis UV dibenarkan), seperti yang diterbitkan NPRA | C9: Annex II versi 2026-1 (10 Jun 2026) disemak bagi no. ruj. 416 (sel, tisu atau produk asal manusia), 419 (bahan Kategori 1 dan 2 menurut definisi ASEAN), 221 (merkuri dan sebatiannya) dan 375 (tretinoin). Bagi Annex III, IV, VI (keluaran 10 Jun 2026) dan VII (12 Dis 2025), hanya tajuk dan tarikh keluaran yang disemak. | D9: https://www.npra.gov.my/images/Guidelines_Central/Guidelines_on_Cosmetic/Annex_II_release_-_10_June_2026.pdf
A10: MS 2627-2 | B10: MS 2627-2:2025 Detection of porcine DNA - Test method - Part 2: Cosmetics, Jabatan Standard Malaysia | C10: Sumber kedua: rekod repositori IIUM (INHART) mengesahkan tajuk, tahun, penerbit dan skop standard ini (qPCR untuk mengenal pasti DNA babi dalam kosmetik pepejal, separa pepejal dan cecair). Teks standard tidak dibaca, jadi tiada nombor klausa dipetik. | D10: http://irep.iium.edu.my/124095/
A11: Fatwa Muzakarah Khas MKI 2011 (alkohol) | B11: Keputusan Muzakarah Khas Jawatankuasa Fatwa Majlis Kebangsaan bagi Hal Ehwal Ugama Islam Malaysia, 14-16 Julai 2011: Isu Alkohol dalam Makanan, Minuman, Pewangi dan Ubat-ubatan | C11: Sumber kedua: Bayan Linnas Siri ke-198 (Jabatan Mufti Wilayah Persekutuan) memetik keputusan ini, iaitu ubat-ubatan dan pewangi yang mengandungi alkohol sebagai bahan pelarut tidak najis dan diharuskan, jika alkohol itu bukan diambil melalui proses pembuatan arak. Portal e-SMAF JAKIM tidak dapat dicapai. | D11: https://www.muftiwp.gov.my/ms/artikel/bayan-linnas/3572-bayan-linnas-siri-ke-198-produk-minuman-yang-menyerupai-arak
A12: Fatwa Muzakarah MKI Kali Ke-100 (cochineal) | B12: Keputusan Muzakarah Jawatankuasa Fatwa Majlis Kebangsaan bagi Hal Ehwal Ugama Islam Malaysia Kali Ke-100, 4-6 Julai 2012, tentang penggunaan pewarna daripada serangga cochineal | C12: Sumber kedua: portal sebenarnya.my memetik keputusan bahawa pewarna cochineal diharuskan dalam makanan, minuman dan barang gunaan, dengan syarat tidak memudaratkan. | D12: https://sebenarnya.my/makanan-mengandungi-bahan-pewarna-cochineal-tidak-halal/
... A15: Perintah Perakuan & Penandaan Halal 2011 | B15: Perintah Perihal Dagangan (Perakuan dan Penandaan Halal) 2011 (P.U.(A) 431/2011) | C15: Teks warta dibaca bagi perenggan 2, 3 (JAKIM dan MAIN sebagai pihak berkuasa berwibawa), 4(1) (makanan dan barang-barang perlu diperakui dan ditanda dengan logo), 5 (barang import), 6 (cara penandaan) dan 8 (kesalahan). | D15: https://login.totalweblite.com/Clients/halalfood/431wartaperakuanhalal.pdf
